2017-11-28 11:19:37,781 ERROR zeus_ads_breakdown_error 139700713023232 - [AdCreativeBreakdownWorking] [_get_ad_creatives] Exception, ad_id:6083148413533, reason:('Connection aborted.', BadStatusLine("''",))
Traceback (most recent call last):
  File "/home/liuyang/wwwroot/zeus/zeus_data_collector_v2/lib/collector/adcreative/adcreative_base.py", line 175, in _get_ad_creatives
    ad_creatives = self.fb_api.get_adcreative_by_adid(ad_id)
  File "/home/liuyang/wwwroot/zeus/zeus_data_collector_v2/lib/facebook_interface.py", line 391, in get_adcreative_by_adid
    AdCreative.Field.status
  File "/home/liuyang/wwwroot/zeus/zeus_data_collector_v2/lib/facebookads/adobjects/ad.py", line 264, in get_ad_creatives
    return request.execute()
  File "/home/liuyang/wwwroot/zeus/zeus_data_collector_v2/lib/facebookads/api.py", line 653, in execute
    cursor.load_next_page()
  File "/home/liuyang/wwwroot/zeus/zeus_data_collector_v2/lib/facebookads/api.py", line 810, in load_next_page
    params=self.params,
  File "/home/liuyang/wwwroot/zeus/zeus_data_collector_v2/lib/facebookads/api.py", line 305, in call
    timeout=self._session.timeout
  File "/usr/local/lib/python2.7/site-packages/requests/sessions.py", line 465, in request
    resp = self.send(prep, **send_kwargs)
  File "/usr/local/lib/python2.7/site-packages/requests/sessions.py", line 573, in send
    r = adapter.send(request, **kwargs)
  File "/usr/local/lib/python2.7/site-packages/requests/adapters.py", line 415, in send
    raise ConnectionError(err, request=request)
ConnectionError: ('Connection aborted.', BadStatusLine("''",))
2017-11-28 11:31:26,388 ERROR zeus_ads_breakdown_error 139701105186560 - [AdCreativeBreakdownWorking] [_get_ad_insights] Exception, ad_id:6087372563702, breakdown_attribute:country, start_dt:2017-11-27, stop_dt:2017-11-27, reason:[]
Traceback (most recent call last):
  File "/home/liuyang/wwwroot/zeus/zeus_data_collector_v2/lib/collector/adcreative/adcreative_breakdown_working.py", line 34, in _get_ad_insights
    ad_insights = self.fb_api.get_ad_insights(ad_id, breakdown_attribute, start_dt, stop_dt)
  File "/home/liuyang/wwwroot/zeus/zeus_data_collector_v2/lib/facebook_interface.py", line 355, in get_ad_insights
    insights = ad.get_insights(params=params)
  File "/home/liuyang/wwwroot/zeus/zeus_data_collector_v2/lib/facebookads/adobjects/ad.py", line 384, in get_insights
    return request.execute()
  File "/home/liuyang/wwwroot/zeus/zeus_data_collector_v2/lib/facebookads/api.py", line 653, in execute
    cursor.load_next_page()
  File "/home/liuyang/wwwroot/zeus/zeus_data_collector_v2/lib/facebookads/api.py", line 810, in load_next_page
    params=self.params,
  File "/home/liuyang/wwwroot/zeus/zeus_data_collector_v2/lib/facebookads/api.py", line 305, in call
    timeout=self._session.timeout
  File "/usr/local/lib/python2.7/site-packages/requests/sessions.py", line 465, in request
    resp = self.send(prep, **send_kwargs)
  File "/usr/local/lib/python2.7/site-packages/requests/sessions.py", line 573, in send
    r = adapter.send(request, **kwargs)
  File "/usr/local/lib/python2.7/site-packages/requests/adapters.py", line 370, in send
    timeout=timeout
  File "/usr/local/lib/python2.7/site-packages/requests/packages/urllib3/connectionpool.py", line 533, in urlopen
    conn = self._get_conn(timeout=pool_timeout)
  File "/usr/local/lib/python2.7/site-packages/requests/packages/urllib3/connectionpool.py", line 239, in _get_conn
    conn.close()
  File "/usr/local/lib/python2.7/httplib.py", line 748, in close
    self.sock.close()   # close it manually... there may be other refs
  File "/usr/local/lib/python2.7/site-packages/requests/packages/urllib3/contrib/pyopenssl.py", line 213, in close
    return self.connection.shutdown()
  File "/usr/local/lib/python2.7/site-packages/OpenSSL/SSL.py", line 1157, in shutdown
    _raise_current_error()
  File "/usr/local/lib/python2.7/site-packages/OpenSSL/_util.py", line 22, in exception_from_error_queue
    raise exceptionType(errors)
Error: []
2017-11-28 11:31:26,411 ERROR zeus_ads_breakdown_error 139701115676416 - [AdCreativeBreakdownWorking] [_get_ads_info_by_adset] Exception, adset_id:6094822222386, reason:[]
Traceback (most recent call last):
  File "/home/liuyang/wwwroot/zeus/zeus_data_collector_v2/lib/collector/adcreative/adcreative_base.py", line 157, in _get_ads_info_by_adset
    ads_info = self.fb_api.get_ads_info_by_adset(adset_id)
  File "/home/liuyang/wwwroot/zeus/zeus_data_collector_v2/lib/facebook_interface.py", line 320, in get_ads_info_by_adset
    Ad.Field.status,
  File "/home/liuyang/wwwroot/zeus/zeus_data_collector_v2/lib/facebookads/adobjects/adset.py", line 454, in get_ads
    return request.execute()
  File "/home/liuyang/wwwroot/zeus/zeus_data_collector_v2/lib/facebookads/api.py", line 653, in execute
    cursor.load_next_page()
  File "/home/liuyang/wwwroot/zeus/zeus_data_collector_v2/lib/facebookads/api.py", line 810, in load_next_page
    params=self.params,
  File "/home/liuyang/wwwroot/zeus/zeus_data_collector_v2/lib/facebookads/api.py", line 305, in call
    timeout=self._session.timeout
  File "/usr/local/lib/python2.7/site-packages/requests/sessions.py", line 465, in request
    resp = self.send(prep, **send_kwargs)
  File "/usr/local/lib/python2.7/site-packages/requests/sessions.py", line 573, in send
    r = adapter.send(request, **kwargs)
  File "/usr/local/lib/python2.7/site-packages/requests/adapters.py", line 370, in send
    timeout=timeout
  File "/usr/local/lib/python2.7/site-packages/requests/packages/urllib3/connectionpool.py", line 533, in urlopen
    conn = self._get_conn(timeout=pool_timeout)
  File "/usr/local/lib/python2.7/site-packages/requests/packages/urllib3/connectionpool.py", line 239, in _get_conn
    conn.close()
  File "/usr/local/lib/python2.7/httplib.py", line 748, in close
    self.sock.close()   # close it manually... there may be other refs
  File "/usr/local/lib/python2.7/site-packages/requests/packages/urllib3/contrib/pyopenssl.py", line 213, in close
    return self.connection.shutdown()
  File "/usr/local/lib/python2.7/site-packages/OpenSSL/SSL.py", line 1157, in shutdown
    _raise_current_error()
  File "/usr/local/lib/python2.7/site-packages/OpenSSL/_util.py", line 22, in exception_from_error_queue
    raise exceptionType(errors)
Error: []
2017-11-28 11:31:26,397 ERROR zeus_ads_breakdown_error 139700723513088 - [AdCreativeBreakdownWorking] [_get_ad_insights] Exception, ad_id:6073894577130, breakdown_attribute:country, start_dt:2017-11-27, stop_dt:2017-11-27, reason:[]
Traceback (most recent call last):
  File "/home/liuyang/wwwroot/zeus/zeus_data_collector_v2/lib/collector/adcreative/adcreative_breakdown_working.py", line 34, in _get_ad_insights
    ad_insights = self.fb_api.get_ad_insights(ad_id, breakdown_attribute, start_dt, stop_dt)
  File "/home/liuyang/wwwroot/zeus/zeus_data_collector_v2/lib/facebook_interface.py", line 355, in get_ad_insights
    insights = ad.get_insights(params=params)
  File "/home/liuyang/wwwroot/zeus/zeus_data_collector_v2/lib/facebookads/adobjects/ad.py", line 384, in get_insights
    return request.execute()
  File "/home/liuyang/wwwroot/zeus/zeus_data_collector_v2/lib/facebookads/api.py", line 653, in execute
    cursor.load_next_page()
  File "/home/liuyang/wwwroot/zeus/zeus_data_collector_v2/lib/facebookads/api.py", line 810, in load_next_page
    params=self.params,
  File "/home/liuyang/wwwroot/zeus/zeus_data_collector_v2/lib/facebookads/api.py", line 305, in call
    timeout=self._session.timeout
  File "/usr/local/lib/python2.7/site-packages/requests/sessions.py", line 465, in request
    resp = self.send(prep, **send_kwargs)
  File "/usr/local/lib/python2.7/site-packages/requests/sessions.py", line 573, in send
    r = adapter.send(request, **kwargs)
  File "/usr/local/lib/python2.7/site-packages/requests/adapters.py", line 370, in send
    timeout=timeout
  File "/usr/local/lib/python2.7/site-packages/requests/packages/urllib3/connectionpool.py", line 533, in urlopen
    conn = self._get_conn(timeout=pool_timeout)
  File "/usr/local/lib/python2.7/site-packages/requests/packages/urllib3/connectionpool.py", line 239, in _get_conn
    conn.close()
  File "/usr/local/lib/python2.7/httplib.py", line 748, in close
    self.sock.close()   # close it manually... there may be other refs
  File "/usr/local/lib/python2.7/site-packages/requests/packages/urllib3/contrib/pyopenssl.py", line 213, in close
    return self.connection.shutdown()
  File "/usr/local/lib/python2.7/site-packages/OpenSSL/SSL.py", line 1157, in shutdown
    _raise_current_error()
  File "/usr/local/lib/python2.7/site-packages/OpenSSL/_util.py", line 22, in exception_from_error_queue
    raise exceptionType(errors)
Error: []
2017-11-28 11:31:26,500 ERROR zeus_ads_breakdown_error 139701094696704 - [AdCreativeBreakdownWorking] [_get_ads_info_by_adset] Exception, adset_id:6098187755365, reason:[]
Traceback (most recent call last):
  File "/home/liuyang/wwwroot/zeus/zeus_data_collector_v2/lib/collector/adcreative/adcreative_base.py", line 157, in _get_ads_info_by_adset
    ads_info = self.fb_api.get_ads_info_by_adset(adset_id)
  File "/home/liuyang/wwwroot/zeus/zeus_data_collector_v2/lib/facebook_interface.py", line 320, in get_ads_info_by_adset
    Ad.Field.status,
  File "/home/liuyang/wwwroot/zeus/zeus_data_collector_v2/lib/facebookads/adobjects/adset.py", line 454, in get_ads
    return request.execute()
  File "/home/liuyang/wwwroot/zeus/zeus_data_collector_v2/lib/facebookads/api.py", line 653, in execute
    cursor.load_next_page()
  File "/home/liuyang/wwwroot/zeus/zeus_data_collector_v2/lib/facebookads/api.py", line 810, in load_next_page
    params=self.params,
  File "/home/liuyang/wwwroot/zeus/zeus_data_collector_v2/lib/facebookads/api.py", line 305, in call
    timeout=self._session.timeout
  File "/usr/local/lib/python2.7/site-packages/requests/sessions.py", line 465, in request
    resp = self.send(prep, **send_kwargs)
  File "/usr/local/lib/python2.7/site-packages/requests/sessions.py", line 573, in send
    r = adapter.send(request, **kwargs)
  File "/usr/local/lib/python2.7/site-packages/requests/adapters.py", line 370, in send
    timeout=timeout
  File "/usr/local/lib/python2.7/site-packages/requests/packages/urllib3/connectionpool.py", line 533, in urlopen
    conn = self._get_conn(timeout=pool_timeout)
  File "/usr/local/lib/python2.7/site-packages/requests/packages/urllib3/connectionpool.py", line 239, in _get_conn
    conn.close()
  File "/usr/local/lib/python2.7/httplib.py", line 748, in close
    self.sock.close()   # close it manually... there may be other refs
  File "/usr/local/lib/python2.7/site-packages/requests/packages/urllib3/contrib/pyopenssl.py", line 213, in close
    return self.connection.shutdown()
  File "/usr/local/lib/python2.7/site-packages/OpenSSL/SSL.py", line 1157, in shutdown
    _raise_current_error()
  File "/usr/local/lib/python2.7/site-packages/OpenSSL/_util.py", line 22, in exception_from_error_queue
    raise exceptionType(errors)
Error: []
2017-11-28 11:31:26,527 ERROR zeus_ads_breakdown_error 139700713023232 - [AdCreativeBreakdownWorking] [_get_ad_insights] Exception, ad_id:6078019723533, breakdown_attribute:country, start_dt:2017-11-27, stop_dt:2017-11-27, reason:(104, 'ECONNRESET')
Traceback (most recent call last):
  File "/home/liuyang/wwwroot/zeus/zeus_data_collector_v2/lib/collector/adcreative/adcreative_breakdown_working.py", line 34, in _get_ad_insights
    ad_insights = self.fb_api.get_ad_insights(ad_id, breakdown_attribute, start_dt, stop_dt)
  File "/home/liuyang/wwwroot/zeus/zeus_data_collector_v2/lib/facebook_interface.py", line 355, in get_ad_insights
    insights = ad.get_insights(params=params)
  File "/home/liuyang/wwwroot/zeus/zeus_data_collector_v2/lib/facebookads/adobjects/ad.py", line 384, in get_insights
    return request.execute()
  File "/home/liuyang/wwwroot/zeus/zeus_data_collector_v2/lib/facebookads/api.py", line 653, in execute
    cursor.load_next_page()
  File "/home/liuyang/wwwroot/zeus/zeus_data_collector_v2/lib/facebookads/api.py", line 810, in load_next_page
    params=self.params,
  File "/home/liuyang/wwwroot/zeus/zeus_data_collector_v2/lib/facebookads/api.py", line 305, in call
    timeout=self._session.timeout
  File "/usr/local/lib/python2.7/site-packages/requests/sessions.py", line 465, in request
    resp = self.send(prep, **send_kwargs)
  File "/usr/local/lib/python2.7/site-packages/requests/sessions.py", line 573, in send
    r = adapter.send(request, **kwargs)
  File "/usr/local/lib/python2.7/site-packages/requests/adapters.py", line 370, in send
    timeout=timeout
  File "/usr/local/lib/python2.7/site-packages/requests/packages/urllib3/connectionpool.py", line 544, in urlopen
    body=body, headers=headers)
  File "/usr/local/lib/python2.7/site-packages/requests/packages/urllib3/connectionpool.py", line 372, in _make_request
    httplib_response = conn.getresponse(buffering=True)
  File "/usr/local/lib/python2.7/httplib.py", line 1013, in getresponse
    response.begin()
  File "/usr/local/lib/python2.7/httplib.py", line 402, in begin
    version, status, reason = self._read_status()
  File "/usr/local/lib/python2.7/httplib.py", line 360, in _read_status
    line = self.fp.readline()
  File "/usr/local/lib/python2.7/socket.py", line 447, in readline
    data = self._sock.recv(self._rbufsize)
  File "/usr/local/lib/python2.7/site-packages/requests/packages/urllib3/contrib/pyopenssl.py", line 171, in recv
    data = self.connection.recv(*args, **kwargs)
  File "/usr/local/lib/python2.7/site-packages/OpenSSL/SSL.py", line 995, in recv
    self._raise_ssl_error(self._ssl, result)
  File "/usr/local/lib/python2.7/site-packages/OpenSSL/SSL.py", line 862, in _raise_ssl_error
    raise SysCallError(errno, errorcode[errno])
SysCallError: (104, 'ECONNRESET')
2017-11-28 11:31:26,547 ERROR zeus_ads_breakdown_error 139701126166272 - [AdCreativeBreakdownWorking] [_get_ad_creatives] Exception, ad_id:6083203315797, reason:(104, 'ECONNRESET')
Traceback (most recent call last):
  File "/home/liuyang/wwwroot/zeus/zeus_data_collector_v2/lib/collector/adcreative/adcreative_base.py", line 175, in _get_ad_creatives
    ad_creatives = self.fb_api.get_adcreative_by_adid(ad_id)
  File "/home/liuyang/wwwroot/zeus/zeus_data_collector_v2/lib/facebook_interface.py", line 391, in get_adcreative_by_adid
    AdCreative.Field.status
  File "/home/liuyang/wwwroot/zeus/zeus_data_collector_v2/lib/facebookads/adobjects/ad.py", line 264, in get_ad_creatives
    return request.execute()
  File "/home/liuyang/wwwroot/zeus/zeus_data_collector_v2/lib/facebookads/api.py", line 653, in execute
    cursor.load_next_page()
  File "/home/liuyang/wwwroot/zeus/zeus_data_collector_v2/lib/facebookads/api.py", line 810, in load_next_page
    params=self.params,
  File "/home/liuyang/wwwroot/zeus/zeus_data_collector_v2/lib/facebookads/api.py", line 305, in call
    timeout=self._session.timeout
  File "/usr/local/lib/python2.7/site-packages/requests/sessions.py", line 465, in request
    resp = self.send(prep, **send_kwargs)
  File "/usr/local/lib/python2.7/site-packages/requests/sessions.py", line 573, in send
    r = adapter.send(request, **kwargs)
  File "/usr/local/lib/python2.7/site-packages/requests/adapters.py", line 370, in send
    timeout=timeout
  File "/usr/local/lib/python2.7/site-packages/requests/packages/urllib3/connectionpool.py", line 544, in urlopen
    body=body, headers=headers)
  File "/usr/local/lib/python2.7/site-packages/requests/packages/urllib3/connectionpool.py", line 372, in _make_request
    httplib_response = conn.getresponse(buffering=True)
  File "/usr/local/lib/python2.7/httplib.py", line 1013, in getresponse
    response.begin()
  File "/usr/local/lib/python2.7/httplib.py", line 402, in begin
    version, status, reason = self._read_status()
  File "/usr/local/lib/python2.7/httplib.py", line 360, in _read_status
    line = self.fp.readline()
  File "/usr/local/lib/python2.7/socket.py", line 447, in readline
    data = self._sock.recv(self._rbufsize)
  File "/usr/local/lib/python2.7/site-packages/requests/packages/urllib3/contrib/pyopenssl.py", line 171, in recv
    data = self.connection.recv(*args, **kwargs)
  File "/usr/local/lib/python2.7/site-packages/OpenSSL/SSL.py", line 995, in recv
    self._raise_ssl_error(self._ssl, result)
  File "/usr/local/lib/python2.7/site-packages/OpenSSL/SSL.py", line 862, in _raise_ssl_error
    raise SysCallError(errno, errorcode[errno])
SysCallError: (104, 'ECONNRESET')
2017-11-28 11:31:26,672 ERROR zeus_ads_breakdown_error 139701084206848 - [AdCreativeBreakdownWorking] [_get_ad_creatives] Exception, ad_id:6086305538624, reason:(104, 'ECONNRESET')
Traceback (most recent call last):
  File "/home/liuyang/wwwroot/zeus/zeus_data_collector_v2/lib/collector/adcreative/adcreative_base.py", line 175, in _get_ad_creatives
    ad_creatives = self.fb_api.get_adcreative_by_adid(ad_id)
  File "/home/liuyang/wwwroot/zeus/zeus_data_collector_v2/lib/facebook_interface.py", line 391, in get_adcreative_by_adid
    AdCreative.Field.status
  File "/home/liuyang/wwwroot/zeus/zeus_data_collector_v2/lib/facebookads/adobjects/ad.py", line 264, in get_ad_creatives
    return request.execute()
  File "/home/liuyang/wwwroot/zeus/zeus_data_collector_v2/lib/facebookads/api.py", line 653, in execute
    cursor.load_next_page()
  File "/home/liuyang/wwwroot/zeus/zeus_data_collector_v2/lib/facebookads/api.py", line 810, in load_next_page
    params=self.params,
  File "/home/liuyang/wwwroot/zeus/zeus_data_collector_v2/lib/facebookads/api.py", line 305, in call
    timeout=self._session.timeout
  File "/usr/local/lib/python2.7/site-packages/requests/sessions.py", line 465, in request
    resp = self.send(prep, **send_kwargs)
  File "/usr/local/lib/python2.7/site-packages/requests/sessions.py", line 573, in send
    r = adapter.send(request, **kwargs)
  File "/usr/local/lib/python2.7/site-packages/requests/adapters.py", line 370, in send
    timeout=timeout
  File "/usr/local/lib/python2.7/site-packages/requests/packages/urllib3/connectionpool.py", line 544, in urlopen
    body=body, headers=headers)
  File "/usr/local/lib/python2.7/site-packages/requests/packages/urllib3/connectionpool.py", line 372, in _make_request
    httplib_response = conn.getresponse(buffering=True)
  File "/usr/local/lib/python2.7/httplib.py", line 1013, in getresponse
    response.begin()
  File "/usr/local/lib/python2.7/httplib.py", line 402, in begin
    version, status, reason = self._read_status()
  File "/usr/local/lib/python2.7/httplib.py", line 360, in _read_status
    line = self.fp.readline()
  File "/usr/local/lib/python2.7/socket.py", line 447, in readline
    data = self._sock.recv(self._rbufsize)
  File "/usr/local/lib/python2.7/site-packages/requests/packages/urllib3/contrib/pyopenssl.py", line 171, in recv
    data = self.connection.recv(*args, **kwargs)
  File "/usr/local/lib/python2.7/site-packages/OpenSSL/SSL.py", line 995, in recv
    self._raise_ssl_error(self._ssl, result)
  File "/usr/local/lib/python2.7/site-packages/OpenSSL/SSL.py", line 862, in _raise_ssl_error
    raise SysCallError(errno, errorcode[errno])
SysCallError: (104, 'ECONNRESET')
2017-11-28 11:31:32,023 ERROR zeus_ads_breakdown_error 139701073716992 - [AdCreativeBreakdownWorking] [_get_ad_insights] Exception, ad_id:6081794322238, breakdown_attribute:country, start_dt:2017-11-27, stop_dt:2017-11-27, reason:[]
Traceback (most recent call last):
  File "/home/liuyang/wwwroot/zeus/zeus_data_collector_v2/lib/collector/adcreative/adcreative_breakdown_working.py", line 34, in _get_ad_insights
    ad_insights = self.fb_api.get_ad_insights(ad_id, breakdown_attribute, start_dt, stop_dt)
  File "/home/liuyang/wwwroot/zeus/zeus_data_collector_v2/lib/facebook_interface.py", line 355, in get_ad_insights
    insights = ad.get_insights(params=params)
  File "/home/liuyang/wwwroot/zeus/zeus_data_collector_v2/lib/facebookads/adobjects/ad.py", line 384, in get_insights
    return request.execute()
  File "/home/liuyang/wwwroot/zeus/zeus_data_collector_v2/lib/facebookads/api.py", line 653, in execute
    cursor.load_next_page()
  File "/home/liuyang/wwwroot/zeus/zeus_data_collector_v2/lib/facebookads/api.py", line 810, in load_next_page
    params=self.params,
  File "/home/liuyang/wwwroot/zeus/zeus_data_collector_v2/lib/facebookads/api.py", line 305, in call
    timeout=self._session.timeout
  File "/usr/local/lib/python2.7/site-packages/requests/sessions.py", line 465, in request
    resp = self.send(prep, **send_kwargs)
  File "/usr/local/lib/python2.7/site-packages/requests/sessions.py", line 573, in send
    r = adapter.send(request, **kwargs)
  File "/usr/local/lib/python2.7/site-packages/requests/adapters.py", line 370, in send
    timeout=timeout
  File "/usr/local/lib/python2.7/site-packages/requests/packages/urllib3/connectionpool.py", line 533, in urlopen
    conn = self._get_conn(timeout=pool_timeout)
  File "/usr/local/lib/python2.7/site-packages/requests/packages/urllib3/connectionpool.py", line 239, in _get_conn
    conn.close()
  File "/usr/local/lib/python2.7/httplib.py", line 748, in close
    self.sock.close()   # close it manually... there may be other refs
  File "/usr/local/lib/python2.7/site-packages/requests/packages/urllib3/contrib/pyopenssl.py", line 213, in close
    return self.connection.shutdown()
  File "/usr/local/lib/python2.7/site-packages/OpenSSL/SSL.py", line 1157, in shutdown
    _raise_current_error()
  File "/usr/local/lib/python2.7/site-packages/OpenSSL/_util.py", line 22, in exception_from_error_queue
    raise exceptionType(errors)
Error: []
